<?xml version="1.0"?>
<robot xmlns:xacro="http://ros.org/wiki/xacro">

<!--
  Author: Felix Messmer
-->

  <xacro:include filename="$(find ur_description)/urdf/ur.transmission.xacro" />
  <xacro:include filename="$(find ur_description)/urdf/ur.gazebo.xacro" />
  <xacro:include filename="$(find ur_description)/urdf/ur.common.xacro" />

  <xacro:macro name="ur3_robot" params="prefix yaml_file">
    <xacro:read_file yaml_file="${yaml_file}"/>
    <xacro:compute_lenght d1="${d1}" a2="${a2}" a3="${a3}"
                          d4="${d4}" d5="${d5}" d6="${d6}"
                          shoulder_offset="${shoulder_offset}" elbow_offset="${elbow_offset}"/>


    <link name="${prefix}base_link" >
      <visual>
        <geometry>
          <mesh filename="package://ur_description/meshes/ur3/visual/base.dae"/>
        </geometry>
        <material name="LightGrey">
          <color rgba="0.7 0.7 0.7 1.0"/>
        </material>
      </visual>
      <collision>
        <geometry>
          <mesh filename="package://ur_description/meshes/ur3/collision/base.stl"/>
        </geometry>
      </collision>
      <xacro:cylinder_inertial radius="0.075" length="0.038" mass="${base_mass}">
        <origin xyz="0.0 0.0 0.0" rpy="0 0 0" />
      </xacro:cylinder_inertial>
    </link>

    <joint name="${prefix}shoulder_pan_joint" type="revolute">
      <parent link="${prefix}base_link" />
      <child link = "${prefix}shoulder_link" />
      <origin xyz="0.0 0.0 ${shoulder_height}" rpy="0.0 0.0 0.0" />
      <axis xyz="0 0 1" />
      <limit lower="${shoulder_pan_lower_limit}" upper="${shoulder_pan_upper_limit}"
          effort="${shoulder_pan_effort_limit}" velocity="${shoulder_pan_velocity_limit}"/>
      <dynamics damping="0.0" friction="0.0"/>
    </joint>

    <link name="${prefix}shoulder_link">
      <visual>
        <geometry>
          <mesh filename="package://ur_description/meshes/ur3/visual/shoulder.dae"/>
        </geometry>
        <material name="LightGrey">
          <color rgba="0.7 0.7 0.7 1.0"/>
        </material>
      </visual>
      <collision>
        <geometry>
          <mesh filename="package://ur_description/meshes/ur3/collision/shoulder.stl"/>
        </geometry>
      </collision>
      <xacro:cylinder_inertial radius="0.075" length="0.178" mass="${shoulder_mass}">
        <origin xyz="0.0 0.0 0.0" rpy="0 0 0" />
      </xacro:cylinder_inertial>
    </link>

    <joint name="${prefix}shoulder_lift_joint" type="revolute">
      <parent link="${prefix}shoulder_link" />
      <child link = "${prefix}upper_arm_link" />
      <origin xyz="0.0 ${shoulder_offset} 0.0" rpy="0.0 ${pi / 2.0} 0.0" />
      <axis xyz="0 1 0" />
      <limit lower="${shoulder_lift_lower_limit}" upper="${shoulder_lift_upper_limit}"
        effort="${shoulder_lift_effort_limit}" velocity="${shoulder_lift_velocity_limit}"/>
      <dynamics damping="0.0" friction="0.0"/>
    </joint>

    <link name="${prefix}upper_arm_link">
      <visual>
        <geometry>
          <mesh filename="package://ur_description/meshes/ur3/visual/upperarm.dae"/>
        </geometry>
        <material name="LightGrey">
          <color rgba="0.7 0.7 0.7 1.0"/>
        </material>
      </visual>
      <collision>
        <geometry>
          <mesh filename="package://ur_description/meshes/ur3/collision/upperarm.stl"/>
        </geometry>
      </collision>
      <xacro:cylinder_inertial radius="0.075" length="${-a2}" mass="${upper_arm_mass}">
        <origin xyz="0.0 0.0 ${-a2/2.0}" rpy="0 0 0" />
      </xacro:cylinder_inertial>
    </link>

    <joint name="${prefix}elbow_joint" type="revolute">
      <parent link="${prefix}upper_arm_link" />
      <child link = "${prefix}forearm_link" />
      <origin xyz="0.0 ${elbow_offset} ${upper_arm_length}" rpy="0.0 0.0 0.0" />
      <axis xyz="0 1 0" />
      <limit lower="${elbow_joint_lower_limit}" upper="${elbow_joint_upper_limit}"
        effort="${elbow_joint_effort_limit}" velocity="${elbow_joint_velocity_limit}"/>
      <dynamics damping="0.0" friction="0.0"/>
    </joint>

    <link name="${prefix}forearm_link">
      <visual>
         <geometry>
          <mesh filename="package://ur_description/meshes/ur3/visual/forearm.dae"/>
        </geometry>
        <material name="LightGrey">
          <color rgba="0.7 0.7 0.7 1.0"/>
        </material>
      </visual>
      <collision>
        <geometry>
          <mesh filename="package://ur_description/meshes/ur3/collision/forearm.stl"/>
        </geometry>
      </collision>
      <xacro:cylinder_inertial radius="0.075" length="${-a3}" mass="${forearm_mass}">
        <origin xyz="0.0 0.0 ${-a3/2.0}" rpy="0 0 0" />
      </xacro:cylinder_inertial>
    </link>

    <joint name="${prefix}wrist_1_joint" type="revolute">
      <parent link="${prefix}forearm_link" />
      <child link = "${prefix}wrist_1_link" />
      <origin xyz="0.0 0.0 ${forearm_length}" rpy="0.0 ${pi / 2.0} 0.0" />
      <axis xyz="0 1 0" />
      <limit lower="${wrist_1_lower_limit}" upper="${wrist_1_upper_limit}"
        effort="${wrist_1_effort_limit}" velocity="${wrist_1_velocity_limit}"/>
      <dynamics damping="0.0" friction="0.0"/>
    </joint>

    <link name="${prefix}wrist_1_link">
      <visual>
        <geometry>
          <mesh filename="package://ur_description/meshes/ur3/visual/wrist1.dae"/>
        </geometry>
        <material name="LightGrey">
          <color rgba="0.7 0.7 0.7 1.0"/>
        </material>
      </visual>
      <collision>
        <geometry>
          <mesh filename="package://ur_description/meshes/ur3/collision/wrist1.stl"/>
        </geometry>
      </collision>
      <xacro:cylinder_inertial radius="0.075" length="0.12" mass="${wrist_1_mass}">
        <origin xyz="0.0 0.0 0.0" rpy="0 0 0" />
      </xacro:cylinder_inertial>
    </link>

    <joint name="${prefix}wrist_2_joint" type="revolute">
      <parent link="${prefix}wrist_1_link" />
      <child link = "${prefix}wrist_2_link" />
      <origin xyz="0.0 ${wrist_1_length} 0.0" rpy="0.0 0.0 0.0" />
      <axis xyz="0 0 1" />
      <limit lower="${wrist_2_lower_limit}" upper="${wrist_2_upper_limit}"
             effort="${wrist_2_effort_limit}" velocity="${wrist_2_velocity_limit}"/>
      <dynamics damping="0.0" friction="0.0"/>
    </joint>

    <link name="${prefix}wrist_2_link">
      <visual>
        <geometry>
          <mesh filename="package://ur_description/meshes/ur3/visual/wrist2.dae"/>
        </geometry>
        <material name="LightGrey">
          <color rgba="0.7 0.7 0.7 1.0"/>
        </material>
      </visual>
      <collision>
        <geometry>
          <mesh filename="package://ur_description/meshes/ur3/collision/wrist2.stl"/>
        </geometry>
      </collision>
      <xacro:cylinder_inertial radius="0.075" length="0.12" mass="${wrist_2_mass}">
        <origin xyz="0.0 0.0 0.0" rpy="0 0 0" />
      </xacro:cylinder_inertial>
    </link>

    <joint name="${prefix}wrist_3_joint" type="revolute">
      <parent link="${prefix}wrist_2_link" />
      <child link = "${prefix}wrist_3_link" />
      <origin xyz="0.0 0.0 ${wrist_2_length}" rpy="0.0 0.0 0.0" />
      <axis xyz="0 1 0" />
      <limit lower="${wrist_3_lower_limit}" upper="${wrist_3_upper_limit}"
             effort="${wrist_3_effort_limit}" velocity="${wrist_3_velocity_limit}"/>
      <dynamics damping="0.0" friction="0.0"/>
    </joint>

    <link name="${prefix}wrist_3_link">
      <visual>
        <geometry>
          <mesh filename="package://ur_description/meshes/ur3/visual/wrist3.dae"/>
        </geometry>
        <material name="LightGrey">
          <color rgba="0.7 0.7 0.7 1.0"/>
        </material>
      </visual>
      <collision>
        <geometry>
          <mesh filename="package://ur_description/meshes/ur3/collision/wrist3.stl"/>
        </geometry>
      </collision>
      <xacro:cylinder_inertial radius="0.075" length="0.12" mass="${wrist_3_mass}">
        <origin xyz="0.0 0.0 0.0" rpy="0 0 0" />
      </xacro:cylinder_inertial>
    </link>

    <joint name="${prefix}ee_fixed_joint" type="fixed">
      <parent link="${prefix}wrist_3_link" />
      <child link = "${prefix}ee_link" />
      <origin xyz="0.0 ${wrist_3_length} 0.0" rpy="0.0 0.0 ${pi/2.0}" />
    </joint>

    <link name="${prefix}ee_link">
      <collision>
        <geometry>
          <box size="0.01 0.01 0.01"/>
        </geometry>
        <origin rpy="0 0 0" xyz="-0.01 0 0"/>
      </collision>
    </link>

    <xacro:ur_arm_transmission prefix="${prefix}" />
    <xacro:ur_arm_gazebo prefix="${prefix}" />

    <!-- ROS base_link to UR 'Base' Coordinates transform -->
    <link name="${prefix}base"/>
    <joint name="${prefix}base_link-base_fixed_joint" type="fixed">
      <!-- NOTE: this rotation is only needed as long as base_link itself is
                 not corrected wrt the real robot (ie: rotated over 180
                 degrees)
      -->
      <origin xyz="0 0 0" rpy="0 0 ${-pi}"/>
      <parent link="${prefix}base_link"/>
      <child link="${prefix}base"/>
    </joint>

    <!-- Frame coincident with all-zeros TCP on UR controller -->
    <link name="${prefix}tool0"/>
    <joint name="${prefix}wrist_3_link-tool0_fixed_joint" type="fixed">
      <origin xyz="0 ${wrist_3_length} 0" rpy="${pi/-2.0} 0 0"/>
      <parent link="${prefix}wrist_3_link"/>
      <child link="${prefix}tool0"/>
    </joint>

  </xacro:macro>
</robot>
